<sdf version='1.11'>
  <model name='double_pendulum'>
    <joint name='fixed' type='fixed'>
      <pose relative_to='__model__'>0 0 0.5 1.5707963267948959 0 0</pose>
      <parent>world</parent>
      <child>base_link</child>
    </joint>
    <link name='base_link'>
      <pose relative_to='fixed'>0 0 0 0 0 0</pose>
      <inertial>
        <pose>0 0 0.02 0 0 0</pose>
        <mass>1.5</mass>
        <inertia>
          <ixx>0.0011375000000000001</ixx>
          <ixy>0</ixy>
          <ixz>0</ixz>
          <iyy>0.0011375000000000001</iyy>
          <iyz>0</iyz>
          <izz>0.0018749999999999999</izz>
        </inertia>
      </inertial>
      <collision name='base_link_collision'>
        <pose>0 0 0.02 0 0 0</pose>
        <geometry>
          <cylinder>
            <length>0.040000000000000001</length>
            <radius>0.050000000000000003</radius>
          </cylinder>
        </geometry>
      </collision>
      <visual name='base_link_visual'>
        <pose>0 0 0.02 0 0 0</pose>
        <geometry>
          <cylinder>
            <length>0.040000000000000001</length>
            <radius>0.050000000000000003</radius>
          </cylinder>
        </geometry>
        <material>
          <diffuse>0 1 0 1</diffuse>
          <ambient>0 1 0 1</ambient>
        </material>
      </visual>
    </link>
    <joint name='joint1' type='revolute'>
      <pose relative_to='base_link'>0 0 0.050000000000000003 0 0 0</pose>
      <parent>base_link</parent>
      <child>link1</child>
      <axis>
        <xyz>0 0 1</xyz>
        <limit>
          <lower>-3.1400000000000001</lower>
          <upper>3.1400000000000001</upper>
          <effort>100</effort>
          <velocity>5</velocity>
        </limit>
        <dynamics>
          <damping>0.10000000000000001</damping>
          <friction>0.01</friction>
          <spring_reference>0</spring_reference>
          <spring_stiffness>0</spring_stiffness>
        </dynamics>
      </axis>
    </joint>
    <link name='link1'>
      <pose relative_to='joint1'>0 0 0 0 0 0</pose>
      <inertial>
        <pose>0.10000000000000001 0 0 0 0 0</pose>
        <mass>1.5</mass>
        <inertia>
          <ixx>0.0001</ixx>
          <ixy>0</ixy>
          <ixz>0</ixz>
          <iyy>0.0061000000000000004</iyy>
          <iyz>0</iyz>
          <izz>0.0061000000000000004</izz>
        </inertia>
      </inertial>
      <collision name='link1_collision'>
        <pose>0.10000000000000001 0 0 0 0 0</pose>
        <geometry>
          <box>
            <size>0.22 0.014999999999999999 0.014999999999999999</size>
          </box>
        </geometry>
      </collision>
      <visual name='link1_visual'>
        <pose>0.10000000000000001 0 0 0 0 0</pose>
        <geometry>
          <box>
            <size>0.22 0.02 0.02</size>
          </box>
        </geometry>
        <material>
          <diffuse>0 0 1 1</diffuse>
          <ambient>0 0 1 1</ambient>
        </material>
      </visual>
    </link>
    <joint name='joint2' type='revolute'>
      <pose relative_to='link1'>0.20000000000000001 0 -0.02 0 0 0</pose>
      <parent>link1</parent>
      <child>link2</child>
      <axis>
        <xyz>0 0 1</xyz>
        <limit>
          <lower>-3.1400000000000001</lower>
          <upper>3.1400000000000001</upper>
          <effort>100</effort>
          <velocity>5</velocity>
        </limit>
        <dynamics>
          <damping>0.10000000000000001</damping>
          <friction>0.01</friction>
          <spring_reference>0</spring_reference>
          <spring_stiffness>0</spring_stiffness>
        </dynamics>
      </axis>
    </joint>
    <link name='link2'>
      <pose relative_to='joint2'>0 0 0 0 0 0</pose>
      <inertial>
        <pose>0.10000000000000001 0 0 0 0 0</pose>
        <mass>1.5</mass>
        <inertia>
          <ixx>0.0001</ixx>
          <ixy>0</ixy>
          <ixz>0</ixz>
          <iyy>0.0061000000000000004</iyy>
          <iyz>0</iyz>
          <izz>0.0061000000000000004</izz>
        </inertia>
      </inertial>
      <collision name='link2_collision'>
        <pose>0.10000000000000001 0 0 0 0 0</pose>
        <geometry>
          <box>
            <size>0.22 0.02 0.02</size>
          </box>
        </geometry>
        <surface>
          <contact>
            <ode/>
          </contact>
          <friction>
            <ode/>
          </friction>
        </surface>
      </collision>
      <visual name='link2_visual'>
        <pose>0.10000000000000001 0 0 0 0 0</pose>
        <geometry>
          <box>
            <size>0.22 0.02 0.02</size>
          </box>
        </geometry>
        <material>
          <diffuse>1 0 0 1</diffuse>
          <ambient>1 0 0 1</ambient>
        </material>
      </visual>
      <sensor name='imu_sensor' type='imu'>
        <always_on>true</always_on>
        <update_rate>100</update_rate>
        <visualize>true</visualize>
        <topic>imu</topic>
        <imu>
          <angular_velocity/>
          <linear_acceleration/>
        </imu>
      </sensor>
    </link>
    <plugin name='gz::sim::systems::Imu' filename='gz-sim-imu-system'/>
    <plugin name='gz::sim::systems::JointStatePublisher' filename='gz-sim-joint-state-publisher-system'/>
    <self_collide>true</self_collide>
    <frame name='tool0_joint' attached_to='link2'>
      <pose>0.20000000000000001 0 0 0 0 0</pose>
    </frame>
    <frame name='tool0' attached_to='tool0_joint'>
      <pose>0 0 0 0 0 0</pose>
    </frame>
  </model>
</sdf>
